<?xml version="1.0"?>
<robot name="diff_drive" xmlns:xacro="http://www.ros.org/wiki/xacro">
    <xacro:property name="yaml_file" value="$(find diff_drive)/params.yaml"/>
    <xacro:property name="props" value="${xacro.load_yaml(yaml_file)['/**']['ros__parameters']}"/>

    <xacro:property name="wheel_props" value="${props['wheel_dimensions']}"/>
    <xacro:property name="caster_props" value="${props['caster_dimensions']}"/>
    <xacro:property name="mass_props" value="${props['masses']}"/>
    <xacro:property name="robot_props" value="${props['robot_dimensions']}"/>

    <!-- Body dimensions -->
    <xacro:property name="a" value="${robot_props['body_length']}" />
    <xacro:property name="b" value="${robot_props['body_height']}" />
    <xacro:property name="c" value="${robot_props['body_width']}" />

    <!-- Wheel dimensions -->
    <xacro:property name="wheel_radius" value="${wheel_props['wheel_radius']}" />
    <xacro:property name="d" value="${wheel_props['wheel_thickness']}" />

    <!-- Caster dimensions -->
    <xacro:property name="r" value="${caster_props['caster_radius']}" />
    
    <!-- Masses -->
    <xacro:property name="m1" value="${mass_props['body_mass']}" />
    <xacro:property name="m2" value="${mass_props['wheel_mass']}" />
    <xacro:property name="m3" value="${mass_props['caster_mass']}" />

    <!-- Positions -->
    <xacro:property name="s1" value="${b/2}" />
    <xacro:property name="s2" value="${2*r}" />
    <xacro:property name="s3" value="${c/2}" />
    <xacro:property name="s4" value="${a/2}" />
    <xacro:property name="s5" value="${b/24}" />

    <xacro:macro name="inertia_body">
        <inertial>
            <mass value="${m1}" />
            <inertia
                ixx="${m1*(b*b + c*c)/12}"
                ixy="0"
                ixz="0"
                iyy="${m1*(a*a + c*c)/12}"
                iyz="0"
                izz="${m1*(a*a + b*b)/12}"
            />
        </inertial>
    </xacro:macro>

    <xacro:macro name="inertia_wheel">
        <inertial>
            <mass value="${m2}" />
            <inertia
                ixx="0.145833"
                ixy="0"
                ixz="0"
                iyy="0.145833"
                iyz="0"
                izz="0.125"
            />
        </inertial>
    </xacro:macro>

    <xacro:macro name="inertia_caster">
        <inertial>
            <mass value="${m3}" />
            <inertia
                ixx="0.0001"
                ixy="0"
                ixz="0"
                iyy="0.0001"
                iyz="0"
                izz="0.0001"
            />
        </inertial>
    </xacro:macro>

    <!-- Main body -->
    <link name="base_link">
        <visual>
            <geometry>
                <box size="${a} ${c} ${b}" />
            </geometry>
            <material name="blue">
                <color rgba="1 0 0 1"/>
              </material>
        </visual>
        <collision>
            <geometry>
                <box size="${a} ${c} ${b}" />
            </geometry>
        </collision>
    </link>

    <!-- Rear left wheel -->
    <link name="wheel_left_link">
        <visual>
            <geometry>
                <cylinder radius="${wheel_radius}" length="${d}" />
            </geometry>
            <material name="red">
                <color rgba="1 1 0 1"/>
              </material>
        </visual>
        <collision>
            <geometry>
                <cylinder radius="${wheel_radius}" length="${d}" />
            </geometry>
        </collision>
        <xacro:inertia_wheel />
    </link>

    <!-- Rear right wheel -->
    <link name="wheel_right_link">
        <visual>
            <geometry>
                <cylinder radius="${wheel_radius}" length="${d}" />
            </geometry>
            <material name="red">
                <color rgba="1 1 0 1"/>
              </material>
        </visual>
        <collision>
            <geometry>
                <cylinder radius="${wheel_radius}" length="${d}" />
            </geometry>
        </collision>
        <xacro:inertia_wheel />
    </link>

    <!-- Front top caster -->
    <link name="front_top_caster_link">
        <visual>
            <geometry>
                <sphere radius="${r/2}" />
            </geometry>
            <material name="yellow">
                <color rgba="1 0 1 1"/>
              </material>
        </visual>
        <collision>
            <geometry>
                <sphere radius="${r/2}" />
            </geometry>
        </collision>
        <xacro:inertia_caster />
    </link>

    <!-- Front bottom caster -->
    <link name="front_bottom_caster_link">
        <visual>
            <geometry>
                <sphere radius="${r/2}" />
            </geometry>
            <material name="yellow">
                <color rgba="1 0 1 1"/>
              </material>
        </visual>
        <collision>
            <geometry>
                <sphere radius="${r/2}" />
            </geometry>
        </collision>
        <xacro:inertia_caster />
    </link>

    <!-- Rear wheels joints -->
    <joint name="wheel_left_joint" type="continuous">
        <parent link="base_link" />
        <child link="wheel_left_link" />
        <origin xyz="${-s4} ${s3} -${s5}" rpy="1.57 0 0" />
        <axis xyz="0 0 1" />
    </joint>

    <joint name="wheel_right_joint" type="continuous">
        <parent link="base_link" />
        <child link="wheel_right_link" />
        <origin xyz="${-s4} -${s3} -${s5}" rpy="1.57 0 0" />
        <axis xyz="0 0 1" />
    </joint>

    <!-- Front top caster joint -->
    <joint name="front_top_caster_joint" type="fixed">
        <parent link="base_link" />
        <child link="front_top_caster_link" />
        <origin xyz="${s4 - 0.1} 0 ${s1}" rpy="0 0 0" />
    </joint>

    <!-- Front bottom caster joint -->
    <joint name="front_bottom_caster_joint" type="fixed">
        <parent link="base_link" />
        <child link="front_bottom_caster_link" />
        <origin xyz="${s4 - 0.1} 0 -${s1}" rpy="0 0 0" />
    </joint>
    <xacro:include filename="$(find diff_drive)/ddrive.gazebo.xacro"/>
</robot>
